ToontownStart: Polling for game2 to finish...
INJECTOR ENABLED
ToontownStart: Game2 is finished.
ToontownStart: Starting the game.
ToontownStart: setting default font
TTLocalizer: Running in language: english
from toontown.toonbase.TTLocalizerEnglish import *
OTPLocalizer: Running in language: english
from otp.otpbase.OTPLocalizerEnglish import *
ToontownStart: Loading default gui sounds
ToontownStart: serverVersion:  sv0.0.0.1-dev
{401000001: <toontown.distributed.ToontownDistrict.ToontownDistrict instance at 0x127F2F08>}
local
1
fisherman origin:  render/scene/daisysGarden/5000:safe_zone/fishing_pond_1/npc_fisherman_origin_0
OnscreenText.configure: mayChange == 0
OnscreenText.configure: mayChange == 0
OnscreenText.configure: mayChange == 0
OnscreenText.configure: mayChange == 0
fisherman origin:  render/scene/toontownCentral/2000:safe_zone/fishing_pond_1/npc_fisherman_origin_0
OnscreenText.configure: mayChange == 0
OnscreenText.configure: mayChange == 0
OnscreenText.configure: mayChange == 0
OnscreenText.configure: mayChange == 0
fisherman origin:  hidden/scene/toontownCentral/2000:safe_zone/fishing_pond_1/npc_fisherman_origin_0
Exception in Tkinter callback
Traceback (most recent call last):
  File "C:\Panda3D-1.9.0\python\lib\lib-tk\Tkinter.py", line 1470, in __call__
    return self.func(*args)
  File "toontown\toonbase\DevInjector.py", line 3, in runInjectorCode
    exec (text.get(1.0, "end"),globals())
  File "<string>", line 2, in <module>
AttributeError: 'NoneType' object has no attribute 'setPos'
Exception in Tkinter callback
Traceback (most recent call last):
  File "C:\Panda3D-1.9.0\python\lib\lib-tk\Tkinter.py", line 1470, in __call__
    return self.func(*args)
  File "toontown\toonbase\DevInjector.py", line 3, in runInjectorCode
    exec (text.get(1.0, "end"),globals())
  File "<string>", line 2, in <module>
AttributeError: 'NoneType' object has no attribute 'setPos'
frame rate: 23.0 fps|0.011d|4 avs||324|325||0x8086|0x0152|1061.9MB|1082.0MB|3967.3MB|653|nt.2.6.2|2.300,2.300|2,2 cpus|OpenGL
Exception in Tkinter callback
Traceback (most recent call last):
  File "C:\Panda3D-1.9.0\python\lib\lib-tk\Tkinter.py", line 1470, in __call__
    return self.func(*args)
  File "toontown\toonbase\DevInjector.py", line 3, in runInjectorCode
    exec (text.get(1.0, "end"),globals())
  File "<string>", line 1, in <module>
NameError: name 'fishCaught' is not defined
Exception occurred while processing Func-updatePos-6182 of Sequence-4564:
Sequence-4564:
  0.000 Sequence-4564 {
  0.000   *Func-updatePos-6182
  0.000   *Func-onMovment-6183
  0.000 }

Traceback (most recent call last):
  File "C:\Panda3D-1.9.0\python\direct\showbase\ShowBase.py", line 1801, in __ivalLoop
    IntervalManager.ivalMgr.step()
  File "C:\Panda3D-1.9.0\python\direct\interval\IntervalManager.py", line 96, in step
    self.__doPythonCallbacks()
  File "C:\Panda3D-1.9.0\python\direct\interval\IntervalManager.py", line 119, in __doPythonCallbacks
    ival.privPostEvent()
  File "C:\Panda3D-1.9.0\python\direct\interval\MetaInterval.py", line 518, in privPostEvent
    self.__doPythonCallbacks()
  File "C:\Panda3D-1.9.0\python\direct\interval\MetaInterval.py", line 494, in __doPythonCallbacks
    ival.privDoEvent(t, eventType)
  File "C:\Panda3D-1.9.0\python\direct\interval\Interval.py", line 207, in privDoEvent
    self.privInstant()
  File "C:\Panda3D-1.9.0\python\direct\interval\FunctionInterval.py", line 88, in privInstant
    self.function(*self.extraArgs, **self.kw)
  File "<string>", line 6, in updatePos
AssertionError: !is_empty() at line 1179 of panda/src/pgraph/nodePath.cxx
Traceback (most recent call last):
  File "otp\otpbase\OTPBase.py", line 238, in run
    taskMgr.run()
  File "C:\Panda3D-1.9.0\python\direct\task\Task.py", line 502, in run
    self.step()
  File "C:\Panda3D-1.9.0\python\direct\task\Task.py", line 460, in step
    self.mgr.poll()
  File "C:\Panda3D-1.9.0\python\direct\showbase\ShowBase.py", line 1801, in __ivalLoop
    IntervalManager.ivalMgr.step()
  File "C:\Panda3D-1.9.0\python\direct\interval\IntervalManager.py", line 96, in step
    self.__doPythonCallbacks()
  File "C:\Panda3D-1.9.0\python\direct\interval\IntervalManager.py", line 119, in __doPythonCallbacks
    ival.privPostEvent()
  File "C:\Panda3D-1.9.0\python\direct\interval\MetaInterval.py", line 518, in privPostEvent
    self.__doPythonCallbacks()
  File "C:\Panda3D-1.9.0\python\direct\interval\MetaInterval.py", line 494, in __doPythonCallbacks
    ival.privDoEvent(t, eventType)
  File "C:\Panda3D-1.9.0\python\direct\interval\Interval.py", line 207, in privDoEvent
    self.privInstant()
  File "C:\Panda3D-1.9.0\python\direct\interval\FunctionInterval.py", line 88, in privInstant
    self.function(*self.extraArgs, **self.kw)
  File "<string>", line 6, in updatePos
AssertionError: !is_empty() at line 1179 of panda/src/pgraph/nodePath.cxx
